[2024-12-20T10:15:16.064+0000] {taskinstance.py:1956} INFO - Dependencies all met for dep_context=non-requeueable deps ti=<TaskInstance: training_pipeline.preprocessing manual__2024-12-20T10:14:56.396102+00:00 [queued]>
[2024-12-20T10:15:16.073+0000] {taskinstance.py:1956} INFO - Dependencies all met for dep_context=requeueable deps ti=<TaskInstance: training_pipeline.preprocessing manual__2024-12-20T10:14:56.396102+00:00 [queued]>
[2024-12-20T10:15:16.074+0000] {taskinstance.py:2170} INFO - Starting attempt 1 of 1
[2024-12-20T10:15:16.089+0000] {taskinstance.py:2191} INFO - Executing <Task(PythonOperator): preprocessing> on 2024-12-20 10:14:56.396102+00:00
[2024-12-20T10:15:16.097+0000] {standard_task_runner.py:60} INFO - Started process 3522 to run task
[2024-12-20T10:15:16.101+0000] {standard_task_runner.py:87} INFO - Running: ['***', 'tasks', 'run', 'training_pipeline', 'preprocessing', 'manual__2024-12-20T10:14:56.396102+00:00', '--job-id', '63', '--raw', '--subdir', 'DAGS_FOLDER/training_pipeline.py', '--cfg-path', '/tmp/tmpzqyf9asl']
[2024-12-20T10:15:16.103+0000] {standard_task_runner.py:88} INFO - Job 63: Subtask preprocessing
[2024-12-20T10:15:16.118+0000] {warnings.py:110} WARNING - /home/***/.local/lib/python3.11/site-packages/***/settings.py:194: DeprecationWarning: The sql_alchemy_conn option in [core] has been moved to the sql_alchemy_conn option in [database] - the old setting has been used, but please update your config.
  SQL_ALCHEMY_CONN = conf.get("database", "SQL_ALCHEMY_CONN")

[2024-12-20T10:15:16.157+0000] {task_command.py:423} INFO - Running <TaskInstance: training_pipeline.preprocessing manual__2024-12-20T10:14:56.396102+00:00 [running]> on host 79bc5a4b2be6
[2024-12-20T10:15:16.541+0000] {taskinstance.py:2480} INFO - Exporting env vars: AIRFLOW_CTX_DAG_OWNER='***' AIRFLOW_CTX_DAG_ID='training_pipeline' AIRFLOW_CTX_TASK_ID='preprocessing' AIRFLOW_CTX_EXECUTION_DATE='2024-12-20T10:14:56.396102+00:00' AIRFLOW_CTX_TRY_NUMBER='1' AIRFLOW_CTX_DAG_RUN_ID='manual__2024-12-20T10:14:56.396102+00:00'
[2024-12-20T10:15:19.618+0000] {warnings.py:110} WARNING - /opt/***/src/features/preprocessing_interim_dagshub_***.py:162: SettingWithCopyWarning: 
A value is trying to be set on a copy of a slice from a DataFrame

See the caveats in the documentation: https://pandas.pydata.org/pandas-docs/stable/user_guide/indexing.html#returning-a-view-versus-a-copy
  data[["houses_dam", "houses_des"]].fillna(0, inplace=True)

[2024-12-20T10:15:19.621+0000] {warnings.py:110} WARNING - /opt/***/src/features/preprocessing_interim_dagshub_***.py:165: SettingWithCopyWarning: 
A value is trying to be set on a copy of a slice from a DataFrame

See the caveats in the documentation: https://pandas.pydata.org/pandas-docs/stable/user_guide/indexing.html#returning-a-view-versus-a-copy
  data[["deaths", "injuries"]].fillna(0, inplace=True)

[2024-12-20T10:15:19.634+0000] {warnings.py:110} WARNING - /opt/***/src/features/preprocessing_interim_dagshub_***.py:180: UserWarning: Boolean Series key will be reindexed to match DataFrame index.
  human_damages = human_damages.sort_values(by="human_damages")[

[2024-12-20T10:15:19.636+0000] {warnings.py:110} WARNING - /opt/***/src/features/preprocessing_interim_dagshub_***.py:183: UserWarning: Boolean Series key will be reindexed to match DataFrame index.
  houses_damages = houses_damages.sort_values(by="houses_damages")[

[2024-12-20T10:15:19.657+0000] {logging_mixin.py:188} INFO - Client created. Use the name of the repo (Data_Atelier) as the name of the 
bucket
[2024-12-20T10:15:19.658+0000] {helpers.py:107} INFO - Client created. Use the name of the repo (Data_Atelier) as the name of the bucket
[2024-12-20T10:15:20.318+0000] {taskinstance.py:2698} ERROR - Task failed with exception
Traceback (most recent call last):
  File "/home/airflow/.local/lib/python3.11/site-packages/airflow/models/taskinstance.py", line 433, in _execute_task
    result = execute_callable(context=context, **execute_callable_kwargs)
             ^^^^^^^^^^^^^^^^^^^^^^^^^^^^^^^^^^^^^^^^^^^^^^^^^^^^^^^^^^^^
  File "/home/airflow/.local/lib/python3.11/site-packages/airflow/operators/python.py", line 199, in execute
    return_value = self.execute_callable()
                   ^^^^^^^^^^^^^^^^^^^^^^^
  File "/home/airflow/.local/lib/python3.11/site-packages/airflow/operators/python.py", line 216, in execute_callable
    return self.python_callable(*self.op_args, **self.op_kwargs)
           ^^^^^^^^^^^^^^^^^^^^^^^^^^^^^^^^^^^^^^^^^^^^^^^^^^^^^
  File "/opt/airflow/src/features/preprocessing_interim_dagshub_airflow.py", line 196, in write_data
    create_table(human_damages, "human_damages.csv")
  File "/opt/airflow/src/features/preprocessing_interim_dagshub_airflow.py", line 44, in create_table
    df.to_csv("/usr/local/data/processed/" + name)
  File "/home/airflow/.local/lib/python3.11/site-packages/pandas/core/generic.py", line 3902, in to_csv
    return DataFrameRenderer(formatter).to_csv(
           ^^^^^^^^^^^^^^^^^^^^^^^^^^^^^^^^^^^^
  File "/home/airflow/.local/lib/python3.11/site-packages/pandas/io/formats/format.py", line 1152, in to_csv
    csv_formatter.save()
  File "/home/airflow/.local/lib/python3.11/site-packages/pandas/io/formats/csvs.py", line 247, in save
    with get_handle(
         ^^^^^^^^^^^
  File "/home/airflow/.local/lib/python3.11/site-packages/pandas/io/common.py", line 739, in get_handle
    check_parent_directory(str(handle))
  File "/home/airflow/.local/lib/python3.11/site-packages/pandas/io/common.py", line 604, in check_parent_directory
    raise OSError(rf"Cannot save file into a non-existent directory: '{parent}'")
OSError: Cannot save file into a non-existent directory: '/usr/local/data/processed'
[2024-12-20T10:15:20.337+0000] {taskinstance.py:1138} INFO - Marking task as FAILED. dag_id=training_pipeline, task_id=preprocessing, execution_date=20241220T101456, start_date=20241220T101516, end_date=20241220T101520
[2024-12-20T10:15:20.358+0000] {standard_task_runner.py:107} ERROR - Failed to execute job 63 for task preprocessing (Cannot save file into a non-existent directory: '/usr/local/data/processed'; 3522)
[2024-12-20T10:15:20.409+0000] {local_task_job_runner.py:234} INFO - Task exited with return code 1
[2024-12-20T10:15:20.447+0000] {taskinstance.py:3280} INFO - 0 downstream tasks scheduled from follow-on schedule check
