[2024-12-20T09:22:05.671+0000] {taskinstance.py:1956} INFO - Dependencies all met for dep_context=non-requeueable deps ti=<TaskInstance: training_pipeline.load_data scheduled__2024-11-12T00:00:00+00:00 [queued]>
[2024-12-20T09:22:05.737+0000] {taskinstance.py:1956} INFO - Dependencies all met for dep_context=requeueable deps ti=<TaskInstance: training_pipeline.load_data scheduled__2024-11-12T00:00:00+00:00 [queued]>
[2024-12-20T09:22:05.759+0000] {taskinstance.py:2170} INFO - Starting attempt 1 of 1
[2024-12-20T09:22:05.821+0000] {taskinstance.py:2191} INFO - Executing <Task(PythonOperator): load_data> on 2024-11-12 00:00:00+00:00
[2024-12-20T09:22:05.851+0000] {standard_task_runner.py:60} INFO - Started process 1643 to run task
[2024-12-20T09:22:05.873+0000] {standard_task_runner.py:87} INFO - Running: ['***', 'tasks', 'run', 'training_pipeline', 'load_data', 'scheduled__2024-11-12T00:00:00+00:00', '--job-id', '25', '--raw', '--subdir', 'DAGS_FOLDER/training_pipeline.py', '--cfg-path', '/tmp/tmp78cmjdbo']
[2024-12-20T09:22:05.890+0000] {standard_task_runner.py:88} INFO - Job 25: Subtask load_data
[2024-12-20T09:22:05.946+0000] {warnings.py:110} WARNING - /home/***/.local/lib/python3.11/site-packages/***/settings.py:194: DeprecationWarning: The sql_alchemy_conn option in [core] has been moved to the sql_alchemy_conn option in [database] - the old setting has been used, but please update your config.
  SQL_ALCHEMY_CONN = conf.get("database", "SQL_ALCHEMY_CONN")

[2024-12-20T09:22:06.131+0000] {task_command.py:423} INFO - Running <TaskInstance: training_pipeline.load_data scheduled__2024-11-12T00:00:00+00:00 [running]> on host 79bc5a4b2be6
[2024-12-20T09:22:06.633+0000] {taskinstance.py:2480} INFO - Exporting env vars: AIRFLOW_CTX_DAG_OWNER='***' AIRFLOW_CTX_DAG_ID='training_pipeline' AIRFLOW_CTX_TASK_ID='load_data' AIRFLOW_CTX_EXECUTION_DATE='2024-11-12T00:00:00+00:00' AIRFLOW_CTX_TRY_NUMBER='1' AIRFLOW_CTX_DAG_RUN_ID='scheduled__2024-11-12T00:00:00+00:00'
[2024-12-20T09:22:06.657+0000] {taskinstance.py:2698} ERROR - Task failed with exception
Traceback (most recent call last):
  File "/home/airflow/.local/lib/python3.11/site-packages/airflow/models/taskinstance.py", line 433, in _execute_task
    result = execute_callable(context=context, **execute_callable_kwargs)
             ^^^^^^^^^^^^^^^^^^^^^^^^^^^^^^^^^^^^^^^^^^^^^^^^^^^^^^^^^^^^
  File "/home/airflow/.local/lib/python3.11/site-packages/airflow/operators/python.py", line 199, in execute
    return_value = self.execute_callable()
                   ^^^^^^^^^^^^^^^^^^^^^^^
  File "/home/airflow/.local/lib/python3.11/site-packages/airflow/operators/python.py", line 216, in execute_callable
    return self.python_callable(*self.op_args, **self.op_kwargs)
           ^^^^^^^^^^^^^^^^^^^^^^^^^^^^^^^^^^^^^^^^^^^^^^^^^^^^^
  File "/opt/airflow/src/data/load_data_s3_dagshub_airflow.py", line 21, in upload_all
    upload_file(path, "tsunamis.csv")
  File "/opt/airflow/src/data/load_data_s3_dagshub_airflow.py", line 14, in upload_file
    s3.upload_file(
  File "/home/airflow/.local/lib/python3.11/site-packages/boto3/s3/inject.py", line 145, in upload_file
    return transfer.upload_file(
           ^^^^^^^^^^^^^^^^^^^^^
  File "/home/airflow/.local/lib/python3.11/site-packages/boto3/s3/transfer.py", line 371, in upload_file
    future.result()
  File "/home/airflow/.local/lib/python3.11/site-packages/s3transfer/futures.py", line 103, in result
    return self._coordinator.result()
           ^^^^^^^^^^^^^^^^^^^^^^^^^^
  File "/home/airflow/.local/lib/python3.11/site-packages/s3transfer/futures.py", line 266, in result
    raise self._exception
  File "/home/airflow/.local/lib/python3.11/site-packages/s3transfer/tasks.py", line 269, in _main
    self._submit(transfer_future=transfer_future, **kwargs)
  File "/home/airflow/.local/lib/python3.11/site-packages/s3transfer/upload.py", line 591, in _submit
    upload_input_manager.provide_transfer_size(transfer_future)
  File "/home/airflow/.local/lib/python3.11/site-packages/s3transfer/upload.py", line 244, in provide_transfer_size
    self._osutil.get_file_size(transfer_future.meta.call_args.fileobj)
  File "/home/airflow/.local/lib/python3.11/site-packages/s3transfer/utils.py", line 251, in get_file_size
    return os.path.getsize(filename)
           ^^^^^^^^^^^^^^^^^^^^^^^^^
  File "<frozen genericpath>", line 50, in getsize
FileNotFoundError: [Errno 2] No such file or directory: 'opt/airflow/data/raw/tsunamis.csv'
[2024-12-20T09:22:06.741+0000] {taskinstance.py:1138} INFO - Marking task as FAILED. dag_id=training_pipeline, task_id=load_data, execution_date=20241112T000000, start_date=20241220T092205, end_date=20241220T092206
[2024-12-20T09:22:06.879+0000] {standard_task_runner.py:107} ERROR - Failed to execute job 25 for task load_data ([Errno 2] No such file or directory: 'opt/airflow/data/raw/tsunamis.csv'; 1643)
[2024-12-20T09:22:06.952+0000] {local_task_job_runner.py:234} INFO - Task exited with return code 1
[2024-12-20T09:22:07.273+0000] {taskinstance.py:3280} INFO - 0 downstream tasks scheduled from follow-on schedule check
