[2024-12-20T09:21:46.445+0000] {taskinstance.py:1956} INFO - Dependencies all met for dep_context=non-requeueable deps ti=<TaskInstance: training_pipeline.load_data scheduled__2024-11-10T00:00:00+00:00 [queued]>
[2024-12-20T09:21:46.463+0000] {taskinstance.py:1956} INFO - Dependencies all met for dep_context=requeueable deps ti=<TaskInstance: training_pipeline.load_data scheduled__2024-11-10T00:00:00+00:00 [queued]>
[2024-12-20T09:21:46.464+0000] {taskinstance.py:2170} INFO - Starting attempt 1 of 1
[2024-12-20T09:21:46.510+0000] {taskinstance.py:2191} INFO - Executing <Task(PythonOperator): load_data> on 2024-11-10 00:00:00+00:00
[2024-12-20T09:21:46.535+0000] {standard_task_runner.py:60} INFO - Started process 1543 to run task
[2024-12-20T09:21:46.550+0000] {standard_task_runner.py:87} INFO - Running: ['***', 'tasks', 'run', 'training_pipeline', 'load_data', 'scheduled__2024-11-10T00:00:00+00:00', '--job-id', '22', '--raw', '--subdir', 'DAGS_FOLDER/training_pipeline.py', '--cfg-path', '/tmp/tmpqdbd3hu1']
[2024-12-20T09:21:46.558+0000] {standard_task_runner.py:88} INFO - Job 22: Subtask load_data
[2024-12-20T09:21:46.605+0000] {warnings.py:110} WARNING - /home/***/.local/lib/python3.11/site-packages/***/settings.py:194: DeprecationWarning: The sql_alchemy_conn option in [core] has been moved to the sql_alchemy_conn option in [database] - the old setting has been used, but please update your config.
  SQL_ALCHEMY_CONN = conf.get("database", "SQL_ALCHEMY_CONN")

[2024-12-20T09:21:46.709+0000] {task_command.py:423} INFO - Running <TaskInstance: training_pipeline.load_data scheduled__2024-11-10T00:00:00+00:00 [running]> on host 79bc5a4b2be6
[2024-12-20T09:21:46.897+0000] {taskinstance.py:2480} INFO - Exporting env vars: AIRFLOW_CTX_DAG_OWNER='***' AIRFLOW_CTX_DAG_ID='training_pipeline' AIRFLOW_CTX_TASK_ID='load_data' AIRFLOW_CTX_EXECUTION_DATE='2024-11-10T00:00:00+00:00' AIRFLOW_CTX_TRY_NUMBER='1' AIRFLOW_CTX_DAG_RUN_ID='scheduled__2024-11-10T00:00:00+00:00'
[2024-12-20T09:21:47.357+0000] {taskinstance.py:2698} ERROR - Task failed with exception
Traceback (most recent call last):
  File "/home/airflow/.local/lib/python3.11/site-packages/airflow/models/taskinstance.py", line 433, in _execute_task
    result = execute_callable(context=context, **execute_callable_kwargs)
             ^^^^^^^^^^^^^^^^^^^^^^^^^^^^^^^^^^^^^^^^^^^^^^^^^^^^^^^^^^^^
  File "/home/airflow/.local/lib/python3.11/site-packages/airflow/operators/python.py", line 199, in execute
    return_value = self.execute_callable()
                   ^^^^^^^^^^^^^^^^^^^^^^^
  File "/home/airflow/.local/lib/python3.11/site-packages/airflow/operators/python.py", line 216, in execute_callable
    return self.python_callable(*self.op_args, **self.op_kwargs)
           ^^^^^^^^^^^^^^^^^^^^^^^^^^^^^^^^^^^^^^^^^^^^^^^^^^^^^
  File "/opt/airflow/src/data/load_data_s3_dagshub_airflow.py", line 21, in upload_all
    upload_file(path, "tsunamis.csv")
  File "/opt/airflow/src/data/load_data_s3_dagshub_airflow.py", line 14, in upload_file
    s3.upload_file(
  File "/home/airflow/.local/lib/python3.11/site-packages/boto3/s3/inject.py", line 145, in upload_file
    return transfer.upload_file(
           ^^^^^^^^^^^^^^^^^^^^^
  File "/home/airflow/.local/lib/python3.11/site-packages/boto3/s3/transfer.py", line 371, in upload_file
    future.result()
  File "/home/airflow/.local/lib/python3.11/site-packages/s3transfer/futures.py", line 103, in result
    return self._coordinator.result()
           ^^^^^^^^^^^^^^^^^^^^^^^^^^
  File "/home/airflow/.local/lib/python3.11/site-packages/s3transfer/futures.py", line 266, in result
    raise self._exception
  File "/home/airflow/.local/lib/python3.11/site-packages/s3transfer/tasks.py", line 269, in _main
    self._submit(transfer_future=transfer_future, **kwargs)
  File "/home/airflow/.local/lib/python3.11/site-packages/s3transfer/upload.py", line 591, in _submit
    upload_input_manager.provide_transfer_size(transfer_future)
  File "/home/airflow/.local/lib/python3.11/site-packages/s3transfer/upload.py", line 244, in provide_transfer_size
    self._osutil.get_file_size(transfer_future.meta.call_args.fileobj)
  File "/home/airflow/.local/lib/python3.11/site-packages/s3transfer/utils.py", line 251, in get_file_size
    return os.path.getsize(filename)
           ^^^^^^^^^^^^^^^^^^^^^^^^^
  File "<frozen genericpath>", line 50, in getsize
FileNotFoundError: [Errno 2] No such file or directory: 'opt/airflow/data/raw/tsunamis.csv'
[2024-12-20T09:21:47.382+0000] {taskinstance.py:1138} INFO - Marking task as FAILED. dag_id=training_pipeline, task_id=load_data, execution_date=20241110T000000, start_date=20241220T092146, end_date=20241220T092147
[2024-12-20T09:21:47.413+0000] {standard_task_runner.py:107} ERROR - Failed to execute job 22 for task load_data ([Errno 2] No such file or directory: 'opt/airflow/data/raw/tsunamis.csv'; 1543)
[2024-12-20T09:21:47.452+0000] {local_task_job_runner.py:234} INFO - Task exited with return code 1
[2024-12-20T09:21:47.498+0000] {taskinstance.py:3280} INFO - 0 downstream tasks scheduled from follow-on schedule check
