[2024-12-20T09:20:27.616+0000] {task_context_logger.py:104} ERROR - Executor reports task instance <TaskInstance: my_dag_2.load_data scheduled__2024-11-17T00:00:00+00:00 [queued]> finished (failed) although the task says it's queued. (Info: None) Was the task killed externally?
